{
  "comments": [
    {
      "key": {
        "uuid": "9ab8dda7_b61c16c3",
        "filename": "sfc/lib/utils.py",
        "patchSetId": 9
      },
      "lineNbr": 428,
      "author": {
        "id": 5579
      },
      "writtenOn": "2017-03-15T07:18:30Z",
      "side": 1,
      "message": "still the avz\u003dnova case is not handled. If even one vnf has the \u0027nova\u0027 availability zone we should check all the computes",
      "range": {
        "startLine": 428,
        "startChar": 0,
        "endLine": 428,
        "endChar": 70
      },
      "revId": "466ee62919198e3d21587e5160b2fae1d8bb40da",
      "serverId": "bbac25d2-bf60-4904-9ba8-a72fc000d6c5",
      "unresolved": false
    }
  ]
}